Workbook

Sheet data
A1: GameID | B1: OPts(Test) | C1: OPassCmp | D1: OPassAtt | E1: OPassPct | F1: OPassYds | G1: OPassTD | H1: ORushAtt | I1: ORushYds | J1: ORushAvg | K1: ORushTD | L1: OTOPlays | M1: OTOYds | N1: OTOAvg | O1: OFDPass | P1: OFDRush | Q1: OFDPen | R1: OFDTot | S1: OPNo | T1: OPYds | U1: OTurnFum | V1: OTurnInt | W1: OTurnTot | X1: DPassCmp | Y1: DPassAtt | Z1: DPassPct | AA1: DPassYds | AB1: DPassTD | AC1: DRushAtt | AD1: DRushYds | AE1: DRushAvg | AF1: DRushTD | AG1: DTOPlays | AH1: DTOYds | AI1: DTOAvg | AJ1: DFDPass | AK1: DFDRush | AL1: DFDPen | AM1: DFDTot | AN1: DPNo | AO1: DPYds | AP1: DTurnFum | AQ1: DTurnInt | AR1: DTurnTO
A2: =CONCATENATE(Scores!A2,"+++",Scores!C2) -> Georgia Tech+++Florida State | B2: =Scores!B2 -> 24 | C2: {=XLOOKUP(LEFT(A2,SEARCH("+",A2)-1),'Offensive Data'!$A$2:$A$134,'Offensive Data'!$D$2:$X$134)} -> 20.7 | D2: 31.7 | E2: 65.3 | F2: 237.5 | G2: 1.3 | H2: 37.8 | I2: 187 | J2: 5 | K2: 2.2 | L2: 69.5 | M2: 424.5 | N2: 6.1 | O2: 10.6 | P2: 9.7 | Q2: 1.3 | R2: 21.6 | S2: 5.4 | T2: 43.3 | U2: 0.2 | V2: 0.5 | W2: 0.8 | X2: {=XLOOKUP(MID(A2, SEARCH("+++", A2) + 3, LEN(A2)),'Defensive Data'!$A$2:$A$134,'Defensive Data'!$D$2:$X$134)} -> 17 | Y2: 27.2 | Z2: 62.6 | AA2: 201.3 | AB2: 1.3 | AC2: 39.8 | AD2: 184.7 | AE2: 4.6 | AF2: 1.8 | AG2: 66.9 | AH2: 385.9 | AI2: 5.8 | AJ2: 9.2 | AK2: 9.7 | AL2: 2.1 | AM2: 20.9 | AN2: 4.8 | AO2: 43.8 | AP2: 0.2 | AQ2: 0.3 | AR2: 0.5
A3: =CONCATENATE(Scores!A3,"+++",Scores!C3) -> Montana State+++New Mexico | B3: =Scores!B3 -> 35 | C3: {=XLOOKUP(LEFT(A3,SEARCH("+",A3)-1),'Offensive Data'!$A$2:$A$134,'Offensive Data'!$D$2:$X$134)} -> #N/A | X3: {=XLOOKUP(MID(A3, SEARCH("+++", A3) + 3, LEN(A3)),'Defensive Data'!$A$2:$A$134,'Defensive Data'!$D$2:$X$134)} -> 21.3 | Y3: 33 | Z3: 64.6 | AA3: 279.2 | AB3: 2.5 | AC3: 39.3 | AD3: 212.9 | AE3: 5.4 | AF3: 2.3 | AG3: 72.3 | AH3: 492.1 | AI3: 6.8 | AJ3: 11.7 | AK3: 10.6 | AL3: 2.4 | AM3: 24.7 | AN3: 7 | AO3: 65.4 | AP3: 0.6 | AQ3: 0.3 | AR3: 0.8
A4: =CONCATENATE(Scores!A4,"+++",Scores!C4) -> Southern Methodist+++Nevada | B4: =Scores!B4 -> 29 | C4: {=XLOOKUP(LEFT(A4,SEARCH("+",A4)-1),'Offensive Data'!$A$2:$A$134,'Offensive Data'!$D$2:$X$134)} -> #N/A | X4: {=XLOOKUP(MID(A4, SEARCH("+++", A4) + 3, LEN(A4)),'Defensive Data'!$A$2:$A$134,'Defensive Data'!$D$2:$X$134)} -> 16.2 | Y4: 26.7 | Z4: 60.5 | AA4: 198.6 | AB4: 1 | AC4: 38.2 | AD4: 192.8 | AE4: 5.1 | AF4: 2.4 | AG4: 64.8 | AH4: 391.5 | AI4: 6 | AJ4: 9.7 | AK4: 10.4 | AL4: 2.8 | AM4: 22.8 | AN4: 5.4 | AO4: 49.2 | AP4: 0.2 | AQ4: 0.8 | AR4: 1
A5: =CONCATENATE(Scores!A5,"+++",Scores!C5) -> Hawaii+++Delaware State | B5: =Scores!B5 -> 35 | C5: {=XLOOKUP(LEFT(A5,SEARCH("+",A5)-1),'Offensive Data'!$A$2:$A$134,'Offensive Data'!$D$2:$X$134)} -> 23.8 | D5: 40 | E5: 59.6 | F5: 268.2 | G5: 2.1 | H5: 28.3 | I5: 97.7 | J5: 3.4 | K5: 0.6 | L5: 68.3 | M5: 365.8 | N5: 5.4 | O5: 12.5 | P5: 5.9 | Q5: 2.3 | R5: 20.8 | S5: 8 | T5: 70.3 | U5: 0.3 | V5: 1.3 | W5: 1.6 | X5: {=XLOOKUP(MID(A5, SEARCH("+++", A5) + 3, LEN(A5)),'Defensive Data'!$A$2:$A$134,'Defensive Data'!$D$2:$X$134)} -> #N/A
A6: =CONCATENATE(Scores!A6,"+++",Scores!C6) -> Alabama-Birmingham+++Alcorn State | B6: =Scores!B6 -> 41 | C6: {=XLOOKUP(LEFT(A6,SEARCH("+",A6)-1),'Offensive Data'!$A$2:$A$134,'Offensive Data'!$D$2:$X$134)} -> #N/A | X6: {=XLOOKUP(MID(A6, SEARCH("+++", A6) + 3, LEN(A6)),'Defensive Data'!$A$2:$A$134,'Defensive Data'!$D$2:$X$134)} -> #N/A
A7: =CONCATENATE(Scores!A7,"+++",Scores!C7) -> Arkansas+++Arkansas-Pine Bluff | B7: =Scores!B7 -> 70 | C7: {=XLOOKUP(LEFT(A7,SEARCH("+",A7)-1),'Offensive Data'!$A$2:$A$134,'Offensive Data'!$D$2:$X$134)} -> 19.6 | D7: 31.8 | E7: 61.6 | F7: 274.7 | G7: 1.2 | H7: 38 | I7: 184.8 | J7: 4.9 | K7: 2.6 | L7: 69.8 | M7: 459.5 | N7: 6.6 | O7: 11.5 | P7: 11.5 | Q7: 1.2 | R7: 24.2 | S7: 7.2 | T7: 59.8 | U7: 1.1 | V7: 0.7 | W7: 1.8 | X7: {=XLOOKUP(MID(A7, SEARCH("+++", A7) + 3, LEN(A7)),'Defensive Data'!$A$2:$A$134,'Defensive Data'!$D$2:$X$134)} -> #N/A
A8: =CONCATENATE(Scores!A8,"+++",Scores!C8) -> Bowling Green+++Fordham | B8: =Scores!B8 -> 41 | C8: {=XLOOKUP(LEFT(A8,SEARCH("+",A8)-1),'Offensive Data'!$A$2:$A$134,'Offensive Data'!$D$2:$X$134)} -> #N/A | X8: {=XLOOKUP(MID(A8, SEARCH("+++", A8) + 3, LEN(A8)),'Defensive Data'!$A$2:$A$134,'Defensive Data'!$D$2:$X$134)} -> #N/A
A9: =CONCATENATE(Scores!A9,"+++",Scores!C9) -> Buffalo+++Lafayette | B9: =Scores!B9 -> 30 | C9: {=XLOOKUP(LEFT(A9,SEARCH("+",A9)-1),'Offensive Data'!$A$2:$A$134,'Offensive Data'!$D$2:$X$134)} -> 14.9 | D9: 26.7 | E9: 55.9 | F9: 186.3 | G9: 1.5 | H9: 41 | I9: 169.1 | J9: 4.1 | K9: 1.8 | L9: 67.7 | M9: 355.4 | N9: 5.3 | O9: 7.9 | P9: 9.2 | Q9: 1.4 | R9: 18.5 | S9: 4.5 | T9: 43.4 | U9: 0.5 | V9: 0.5 | W9: 1 | X9: {=XLOOKUP(MID(A9, SEARCH("+++", A9) + 3, LEN(A9)),'Defensive Data'!$A$2:$A$134,'Defensive Data'!$D$2:$X$134)} -> #N/A
A10: =CONCATENATE(Scores!A10,"+++",Scores!C10) -> Central Florida+++New Hampshire | B10: =Scores!B10 -> 57 | C10: {=XLOOKUP(LEFT(A10,SEARCH("+",A10)-1),'Offensive Data'!$A$2:$A$134,'Offensive Data'!$D$2:$X$134)} -> #N/A | X10: {=XLOOKUP(MID(A10, SEARCH("+++", A10) + 3, LEN(A10)),'Defensive Data'!$A$2:$A$134,'Defensive Data'!$D$2:$X$134)} -> #N/A
A11: =CONCATENATE(Scores!A11,"+++",Scores!C11) -> Central Michigan+++Central Connecticut State | B11: =Scores!B11 -> 66 | C11: {=XLOOKUP(LEFT(A11,SEARCH("+",A11)-1),'Offensive Data'!$A$2:$A$134,'Offensive Data'!$D$2:$X$134)} -> 13.9 | D11: 25.2 | E11: 55.3 | F11: 163.4 | G11: 0.9 | H11: 37.3 | I11: 166.1 | J11: 4.5 | K11: 1.4 | L11: 62.4 | M11: 329.5 | N11: 5.3 | O11: 6.9 | P11: 8.8 | Q11: 2.3 | R11: 18 | S11: 6.8 | T11: 60.9 | U11: 0.8 | V11: 1 | W11: 1.8 | X11: {=XLOOKUP(MID(A11, SEARCH("+++", A11) + 3, LEN(A11)),'Defensive Data'!$A$2:$A$134,'Defensive Data'!$D$2:$X$134)} -> #N/A
A12: =CONCATENATE(Scores!A12,"+++",Scores!C12) -> Coastal Carolina+++Jacksonville State | B12: =Scores!B12 -> 55 | C12: {=XLOOKUP(LEFT(A12,SEARCH("+",A12)-1),'Offensive Data'!$A$2:$A$134,'Offensive Data'!$D$2:$X$134)} -> 15 | D12: 27.6 | E12: 54.3 | F12: 202 | G12: 1.5 | H12: 37.2 | I12: 172.5 | J12: 4.6 | K12: 1.6 | L12: 64.8 | M12: 374.5 | N12: 5.8 | O12: 7.9 | P12: 8.4 | Q12: 1.8 | R12: 18.1 | S12: 6.9 | T12: 63.8 | U12: 0.5 | V12: 0.8 | W12: 1.3 | X12: {=XLOOKUP(MID(A12, SEARCH("+++", A12) + 3, LEN(A12)),'Defensive Data'!$A$2:$A$134,'Defensive Data'!$D$2:$X$134)} -> 17.6 | Y12: 29.3 | Z12: 60.2 | AA12: 218.2 | AB12: 1.5 | AC12: 41 | AD12: 174.8 | AE12: 4.3 | AF12: 1.5 | AG12: 70.3 | AH12: 393 | AI12: 5.6 | AJ12: 10.1 | AK12: 9.1 | AL12: 2.5 | AM12: 21.7 | AN12: 6.1 | AO12: 56.9 | AP12: 0.9 | AQ12: 0.9 | AR12: 1.7
A13: =CONCATENATE(Scores!A13,"+++",Scores!C13) -> Colorado+++North Dakota State | B13: =Scores!B13 -> 31 | C13: {=XLOOKUP(LEFT(A13,SEARCH("+",A13)-1),'Offensive Data'!$A$2:$A$134,'Offensive Data'!$D$2:$X$134)} -> 27.2 | D13: 37.1 | E13: 73.2 | F13: 318 | G13: 2.8 | H13: 26.2 | I13: 65.2 | J13: 2.5 | K13: 1.2 | L13: 63.3 | M13: 383.2 | N13: 6.1 | O13: 13.2 | P13: 4.8 | Q13: 2.4 | R13: 20.4 | S13: 7.7 | T13: 67.8 | U13: 0.4 | V13: 0.8 | W13: 1.2 | X13: {=XLOOKUP(MID(A13, SEARCH("+++", A13) + 3, LEN(A13)),'Defensive Data'!$A$2:$A$134,'Defensive Data'!$D$2:$X$134)} -> #N/A
A14: =CONCATENATE(Scores!A14,"+++",Scores!C14) -> Illinois+++Eastern Illinois | B14: =Scores!B14 -> 45 | C14: {=XLOOKUP(LEFT(A14,SEARCH("+",A14)-1),'Offensive Data'!$A$2:$A$134,'Offensive Data'!$D$2:$X$134)} -> 16.4 | D14: 27.2 | E14: 60.3 | F14: 211.2 | G14: 1.7 | H14: 34.8 | I14: 153.6 | J14: 4.4 | K14: 1.7 | L14: 61.9 | M14: 364.8 | N14: 5.9 | O14: 9.8 | P14: 8.5 | Q14: 2.2 | R14: 20.4 | S14: 5.2 | T14: 40.2 | U14: 0.6 | V14: 0.5 | W14: 1.1 | X14: {=XLOOKUP(MID(A14, SEARCH("+++", A14) + 3, LEN(A14)),'Defensive Data'!$A$2:$A$134,'Defensive Data'!$D$2:$X$134)} -> #N/A
A15: =CONCATENATE(Scores!A15,"+++",Scores!C15) -> Kansas+++Lindenwood | B15: =Scores!B15 -> 48 | C15: {=XLOOKUP(LEFT(A15,SEARCH("+",A15)-1),'Offensive Data'!$A$2:$A$134,'Offensive Data'!$D$2:$X$134)} -> 14.7 | D15: 25.5 | E15: 57.5 | F15: 208.8 | G15: 1.3 | H15: 38.3 | I15: 211.4 | J15: 5.5 | K15: 2.4 | L15: 63.8 | M15: 420.2 | N15: 6.6 | O15: 9 | P15: 11.1 | Q15: 1.4 | R15: 21.5 | S15: 4.5 | T15: 38.7 | U15: 0.4 | V15: 1 | W15: 1.4 | X15: {=XLOOKUP(MID(A15, SEARCH("+++", A15) + 3, LEN(A15)),'Defensive Data'!$A$2:$A$134,'Defensive Data'!$D$2:$X$134)} -> #N/A
A16: =CONCATENATE(Scores!A16,"+++",Scores!C16) -> Louisiana-Monroe+++Jackson State | B16: =Scores!B16 -> 30 | C16: {=XLOOKUP(LEFT(A16,SEARCH("+",A16)-1),'Offensive Data'!$A$2:$A$134,'Offensive Data'!$D$2:$X$134)} -> 11.2 | D16: 20.5 | E16: 54.5 | F16: 134.8 | G16: 0.9 | H16: 38 | I16: 169.7 | J16: 4.5 | K16: 1.4 | L16: 58.5 | M16: 304.4 | N16: 5.2 | O16: 5.6 | P16: 8.3 | Q16: 1.6 | R16: 15.4 | S16: 5.9 | T16: 43.3 | U16: 0.3 | V16: 1 | W16: 1.3 | X16: {=XLOOKUP(MID(A16, SEARCH("+++", A16) + 3, LEN(A16)),'Defensive Data'!$A$2:$A$134,'Defensive Data'!$D$2:$X$134)} -> #N/A
A17: =CONCATENATE(Scores!A17,"+++",Scores!C17) -> Missouri+++Murray State | B17: =Scores!B17 -> 51 | C17: {=XLOOKUP(LEFT(A17,SEARCH("+",A17)-1),'Offensive Data'!$A$2:$A$134,'Offensive Data'!$D$2:$X$134)} -> 19.2 | D17: 31.1 | E17: 61.9 | F17: 225.1 | G17: 1.1 | H17: 39.8 | I17: 164.5 | J17: 4.1 | K17: 2 | L17: 70.9 | M17: 389.5 | N17: 5.5 | O17: 9.2 | P17: 10.5 | Q17: 1.5 | R17: 21.2 | S17: 5.6 | T17: 50.6 | U17: 0.3 | V17: 0.4 | W17: 0.7 | X17: {=XLOOKUP(MID(A17, SEARCH("+++", A17) + 3, LEN(A17)),'Defensive Data'!$A$2:$A$134,'Defensive Data'!$D$2:$X$134)} -> #N/A
A18: =CONCATENATE(Scores!A18,"+++",Scores!C18) -> North Carolina+++Minnesota | B18: =Scores!B18 -> 19 | C18: {=XLOOKUP(LEFT(A18,SEARCH("+",A18)-1),'Offensive Data'!$A$2:$A$134,'Offensive Data'!$D$2:$X$134)} -> 17.7 | D18: 30.2 | E18: 58.7 | F18: 224.4 | G18: 1.4 | H18: 38.2 | I18: 182.3 | J18: 4.8 | K18: 2 | L18: 68.3 | M18: 406.7 | N18: 6 | O18: 9.4 | P18: 9.6 | Q18: 2 | R18: 21 | S18: 7.5 | T18: 64 | U18: 0.6 | V18: 0.7 | W18: 1.3 | X18: {=XLOOKUP(MID(A18, SEARCH("+++", A18) + 3, LEN(A18)),'Defensive Data'!$A$2:$A$134,'Defensive Data'!$D$2:$X$134)} -> 16.9 | Y18: 28.7 | Z18: 59 | AA18: 176.1 | AB18: 0.8 | AC18: 31.3 | AD18: 109.6 | AE18: 3.5 | AF18: 1.1 | AG18: 60 | AH18: 285.7 | AI18: 4.8 | AJ18: 8.5 | AK18: 5.9 | AL18: 1.5 | AM18: 16 | AN18: 5 | AO18: 49.1 | AP18: 0.3 | AQ18: 1.3 | AR18: 1.6
A19: =CONCATENATE(Scores!A19,"+++",Scores!C19) -> North Carolina State+++Western Carolina | B19: =Scores!B19 -> 38 | C19: {=XLOOKUP(LEFT(A19,SEARCH("+",A19)-1),'Offensive Data'!$A$2:$A$134,'Offensive Data'!$D$2:$X$134)} -> 19.6 | D19: 30.1 | E19: 65.2 | F19: 232.6 | G19: 1.6 | H19: 32.4 | I19: 145.2 | J19: 4.5 | K19: 1.6 | L19: 62.5 | M19: 377.8 | N19: 6 | O19: 10.5 | P19: 7.3 | Q19: 2.3 | R19: 20.2 | S19: 5.1 | T19: 47.8 | U19: 0.8 | V19: 1 | W19: 1.8 | X19: {=XLOOKUP(MID(A19, SEARCH("+++", A19) + 3, LEN(A19)),'Defensive Data'!$A$2:$A$134,'Defensive Data'!$D$2:$X$134)} -> #N/A
A20: =CONCATENATE(Scores!A20,"+++",Scores!C20) -> Rutgers+++Howard | B20: =Scores!B20 -> 44 | C20: {=XLOOKUP(LEFT(A20,SEARCH("+",A20)-1),'Offensive Data'!$A$2:$A$134,'Offensive Data'!$D$2:$X$134)} -> 16.4 | D20: 30.4 | E20: 53.9 | F20: 207.4 | G20: 1.4 | H20: 39.8 | I20: 175.3 | J20: 4.4 | K20: 2.2 | L20: 70.2 | M20: 382.7 | N20: 5.5 | O20: 10.1 | P20: 9.9 | Q20: 2.5 | R20: 22.5 | S20: 4 | T20: 34.2 | U20: 0.2 | V20: 0.5 | W20: 0.7 | X20: {=XLOOKUP(MID(A20, SEARCH("+++", A20) + 3, LEN(A20)),'Defensive Data'!$A$2:$A$134,'Defensive Data'!$D$2:$X$134)} -> #N/A
A21: =CONCATENATE(Scores!A21,"+++",Scores!C21) -> San Jose State+++Sacramento State | B21: =Scores!B21 -> 42 | C21: {=XLOOKUP(LEFT(A21,SEARCH("+",A21)-1),'Offensive Data'!$A$2:$A$134,'Offensive Data'!$D$2:$X$134)} -> 24.3 | D21: 42.5 | E21: 57.2 | F21: 321.8 | G21: 2.4 | H21: 24.9 | I21: 88.1 | J21: 3.5 | K21: 1 | L21: 67.4 | M21: 409.8 | N21: 6.1 | O21: 13.8 | P21: 5.5 | Q21: 2.5 | R21: 21.8 | S21: 7 | T21: 60.3 | U21: 1 | V21: 1.2 | W21: 2.2 | X21: {=XLOOKUP(MID(A21, SEARCH("+++", A21) + 3, LEN(A21)),'Defensive Data'!$A$2:$A$134,'Defensive Data'!$D$2:$X$134)} -> #N/A
A22: =CONCATENATE(Scores!A22,"+++",Scores!C22) -> Toledo+++Duquesne | B22: =Scores!B22 -> 49 | C22: {=XLOOKUP(LEFT(A22,SEARCH("+",A22)-1),'Offensive Data'!$A$2:$A$134,'Offensive Data'!$D$2:$X$134)} -> 21.2 | D22: 34.8 | E22: 60.9 | F22: 254.2 | G22: 2.2 | H22: 33.5 | I22: 115.7 | J22: 3.4 | K22: 1 | L22: 68.4 | M22: 369.9 | N22: 5.4 | O22: 11.1 | P22: 6.2 | Q22: 2.5 | R22: 19.8 | S22: 6.4 | T22: 56.8 | U22: 0.8 | V22: 0.6 | W22: 1.5 | X22: {=XLOOKUP(MID(A22, SEARCH("+++", A22) + 3, LEN(A22)),'Defensive Data'!$A$2:$A$134,'Defensive Data'!$D$2:$X$134)} -> #N/A
A23: =CONCATENATE(Scores!A23,"+++",Scores!C23) -> Tulane+++Southeastern Louisiana | B23: =Scores!B23 -> 52 | C23: {=XLOOKUP(LEFT(A23,SEARCH("+",A23)-1),'Offensive Data'!$A$2:$A$134,'Offensive Data'!$D$2:$X$134)} -> 14.8 | D23: 23.5 | E23: 62.9 | F23: 209.4 | G23: 1.8 | H23: 40.5 | I23: 195.6 | J23: 4.8 | K23: 2.3 | L23: 64 | M23: 405 | N23: 6.3 | O23: 8.5 | P23: 10.5 | Q23: 1.8 | R23: 20.8 | S23: 6.1 | T23: 50.1 | U23: 0.4 | V23: 0.6 | W23: 1.1 | X23: {=XLOOKUP(MID(A23, SEARCH("+++", A23) + 3, LEN(A23)),'Defensive Data'!$A$2:$A$134,'Defensive Data'!$D$2:$X$134)} -> #N/A
A24: =CONCATENATE(Scores!A24,"+++",Scores!C24) -> Tulsa+++Northwestern State | B24: =Scores!B24 -> 62 | C24: {=XLOOKUP(LEFT(A24,SEARCH("+",A24)-1),'Offensive Data'!$A$2:$A$134,'Offensive Data'!$D$2:$X$134)} -> 20.7 | D24: 36.5 | E24: 56.6 | F24: 238.6 | G24: 1.9 | H24: 37.6 | I24: 151.1 | J24: 4 | K24: 0.9 | L24: 74.1 | M24: 389.7 | N24: 5.3 | O24: 10.2 | P24: 7.6 | Q24: 2.8 | R24: 20.6 | S24: 5.9 | T24: 51 | U24: 0.8 | V24: 1 | W24: 1.8 | X24: {=XLOOKUP(MID(A24, SEARCH("+++", A24) + 3, LEN(A24)),'Defensive Data'!$A$2:$A$134,'Defensive Data'!$D$2:$X$134)} -> #N/A
A25: =CONCATENATE(Scores!A25,"+++",Scores!C25) -> Utah+++Southern Utah | B25: =Scores!B25 -> 49 | C25: {=XLOOKUP(LEFT(A25,SEARCH("+",A25)-1),'Offensive Data'!$A$2:$A$134,'Offensive Data'!$D$2:$X$134)} -> 16.6 | D25: 29.8 | E25: 55.6 | F25: 199.4 | G25: 1.7 | H25: 33.6 | I25: 130.4 | J25: 3.9 | K25: 0.6 | L25: 63.4 | M25: 329.8 | N25: 5.2 | O25: 8.6 | P25: 6.8 | Q25: 1.3 | R25: 16.6 | S25: 5.4 | T25: 46.3 | U25: 0.4 | V25: 1.4 | W25: 1.8 | X25: {=XLOOKUP(MID(A25, SEARCH("+++", A25) + 3, LEN(A25)),'Defensive Data'!$A$2:$A$134,'Defensive Data'!$D$2:$X$134)} -> #N/A
A26: =CONCATENATE(Scores!A26,"+++",Scores!C26) -> Wake Forest+++North Carolina A&T | B26: =Scores!B26 -> 45 | C26: {=XLOOKUP(LEFT(A26,SEARCH("+",A26)-1),'Offensive Data'!$A$2:$A$134,'Offensive Data'!$D$2:$X$134)} -> 20.7 | D26: 33.7 | E26: 61.4 | F26: 240.1 | G26: 1.4 | H26: 37 | I26: 130.6 | J26: 3.5 | K26: 1.5 | L26: 70.7 | M26: 370.7 | N26: 5.2 | O26: 11.3 | P26: 7.8 | Q26: 2.7 | R26: 21.8 | S26: 5.1 | T26: 45.9 | U26: 0.7 | V26: 1.1 | W26: 1.8 | X26: {=XLOOKUP(MID(A26, SEARCH("+++", A26) + 3, LEN(A26)),'Defensive Data'!$A$2:$A$134,'Defensive Data'!$D$2:$X$134)} -> #N/A
A27: =CONCATENATE(Scores!A27,"+++",Scores!C27) -> Army+++Lehigh | B27: =Scores!B27 -> 42 | C27: {=XLOOKUP(LEFT(A27,SEARCH("+",A27)-1),'Offensive Data'!$A$2:$A$134,'Offensive Data'!$D$2:$X$134)} -> 4.7 | D27: 8.7 | E27: 54.1 | F27: 80.6 | G27: 0.7 | H27: 54.6 | I27: 300.5 | J27: 5.5 | K27: 3.4 | L27: 63.3 | M27: 381.1 | N27: 6 | O27: 3.1 | P27: 16.4 | Q27: 1.3 | R27: 20.9 | S27: 3.2 | T27: 31.5 | U27: 0.4 | V27: 0.3 | W27: 0.6 | X27: {=XLOOKUP(MID(A27, SEARCH("+++", A27) + 3, LEN(A27)),'Defensive Data'!$A$2:$A$134,'Defensive Data'!$D$2:$X$134)} -> #N/A
A28: =CONCATENATE(Scores!A28,"+++",Scores!C28) -> Duke+++Elon | B28: =Scores!B28 -> 26 | C28: {=XLOOKUP(LEFT(A28,SEARCH("+",A28)-1),'Offensive Data'!$A$2:$A$134,'Offensive Data'!$D$2:$X$134)} -> 21.5 | D28: 35.9 | E28: 60 | F28: 244.3 | G28: 2.2 | H28: 29.3 | I28: 92.5 | J28: 3.2 | K28: 1 | L28: 65.2 | M28: 336.8 | N28: 5.2 | O28: 10.8 | P28: 4.6 | Q28: 2.2 | R28: 17.6 | S28: 5.2 | T28: 50.1 | U28: 0.5 | V28: 1 | W28: 1.5 | X28: {=XLOOKUP(MID(A28, SEARCH("+++", A28) + 3, LEN(A28)),'Defensive Data'!$A$2:$A$134,'Defensive Data'!$D$2:$X$134)} -> #N/A
A29: =CONCATENATE(Scores!A29,"+++",Scores!C29) -> Michigan State+++Florida Atlantic | B29: =Scores!B29 -> 16 | C29: {=XLOOKUP(LEFT(A29,SEARCH("+",A29)-1),'Offensive Data'!$A$2:$A$134,'Offensive Data'!$D$2:$X$134)} -> 17.7 | D29: 29.4 | E29: 60.1 | F29: 218.1 | G29: 1.1 | H29: 32.8 | I29: 116.3 | J29: 3.6 | K29: 0.9 | L29: 62.2 | M29: 334.4 | N29: 5.4 | O29: 9.2 | P29: 8.3 | Q29: 1.4 | R29: 18.8 | S29: 6.7 | T29: 63.3 | U29: 0.6 | V29: 1 | W29: 1.6 | X29: {=XLOOKUP(MID(A29, SEARCH("+++", A29) + 3, LEN(A29)),'Defensive Data'!$A$2:$A$134,'Defensive Data'!$D$2:$X$134)} -> 17.6 | Y29: 31.5 | Z29: 55.8 | AA29: 233.2 | AB29: 2.1 | AC29: 37.5 | AD29: 183.5 | AE29: 4.9 | AF29: 1.5 | AG29: 69 | AH29: 416.7 | AI29: 6 | AJ29: 9.8 | AK29: 9.3 | AL29: 1.9 | AM29: 21 | AN29: 6 | AO29: 52.5 | AP29: 0.6 | AQ29: 0.9 | AR29: 1.5
A30: =CONCATENATE(Scores!A30,"+++",Scores!C30) -> Oklahoma+++Temple | B30: =Scores!B30 -> 51 | C30: {=XLOOKUP(LEFT(A30,SEARCH("+",A30)-1),'Offensive Data'!$A$2:$A$134,'Offensive Data'!$D$2:$X$134)} -> 18.1 | D30: 28.7 | E30: 63 | F30: 175.8 | G30: 1.2 | H30: 40.1 | I30: 155.2 | J30: 3.9 | K30: 1.3 | L30: 68.8 | M30: 331 | N30: 4.8 | O30: 7.7 | P30: 9.2 | Q30: 2.1 | R30: 19 | S30: 5.3 | T30: 45.5 | U30: 1.2 | V30: 0.5 | W30: 1.6 | X30: {=XLOOKUP(MID(A30, SEARCH("+++", A30) + 3, LEN(A30)),'Defensive Data'!$A$2:$A$134,'Defensive Data'!$D$2:$X$134)} -> 16.3 | Y30: 27.8 | Z30: 58.9 | AA30: 191.7 | AB30: 1.7 | AC30: 40.8 | AD30: 226.1 | AE30: 5.5 | AF30: 2.5 | AG30: 68.6 | AH30: 417.8 | AI30: 6.1 | AJ30: 8.4 | AK30: 10 | AL30: 1.6 | AM30: 20 | AN30: 5.4 | AO30: 47.1 | AP30: 0.5 | AQ30: 0.8 | AR30: 1.3
A31: =CONCATENATE(Scores!A31,"+++",Scores!C31) -> Texas Christian+++Stanford | B31: =Scores!B31 -> 34 | C31: {=XLOOKUP(LEFT(A31,SEARCH("+",A31)-1),'Offensive Data'!$A$2:$A$134,'Offensive Data'!$D$2:$X$134)} -> #N/A | X31: {=XLOOKUP(MID(A31, SEARCH("+++", A31) + 3, LEN(A31)),'Defensive Data'!$A$2:$A$134,'Defensive Data'!$D$2:$X$134)} -> 21.9 | Y31: 33.2 | Z31: 66.1 | AA31: 280.6 | AB31: 2.6 | AC31: 31.6 | AD31: 133.5 | AE31: 4.2 | AF31: 1.8 | AG31: 64.8 | AH31: 414.1 | AI31: 6.4 | AJ31: 12.4 | AK31: 7.3 | AL31: 1.5 | AM31: 21.2 | AN31: 6.8 | AO31: 61.8 | AP31: 0.7 | AQ31: 0.8 | AR31: 1.4
A32: =CONCATENATE(Scores!A32,"+++",Scores!C32) -> Wisconsin+++Western Michigan | B32: =Scores!B32 -> 28 | C32: {=XLOOKUP(LEFT(A32,SEARCH("+",A32)-1),'Offensive Data'!$A$2:$A$134,'Offensive Data'!$D$2:$X$134)} -> 17.3 | D32: 30.4 | E32: 57 | F32: 196.7 | G32: 1.2 | H32: 35.2 | I32: 153.7 | J32: 4.4 | K32: 1.6 | L32: 65.6 | M32: 350.3 | N32: 5.3 | O32: 8.2 | P32: 8.7 | Q32: 1.9 | R32: 18.8 | S32: 5.3 | T32: 37.5 | U32: 0.7 | V32: 0.8 | W32: 1.5 | X32: {=XLOOKUP(MID(A32, SEARCH("+++", A32) + 3, LEN(A32)),'Defensive Data'!$A$2:$A$134,'Defensive Data'!$D$2:$X$134)} -> 16.2 | Y32: 26.5 | Z32: 61.3 | AA32: 222.6 | AB32: 1.5 | AC32: 38.5 | AD32: 192.5 | AE32: 5 | AF32: 2.2 | AG32: 64.9 | AH32: 415.1 | AI32: 6.4 | AJ32: 9.5 | AK32: 10.1 | AL32: 1.6 | AM32: 21.2 | AN32: 4.6 | AO32: 38.7 | AP32: 1 | AQ32: 0.6 | AR32: 1.6
A33: =CONCATENATE(Scores!A33,"+++",Scores!C33) -> Air Force+++Merrimack | B33: =Scores!B33 -> 21 | C33: {=XLOOKUP(LEFT(A33,SEARCH("+",A33)-1),'Offensive Data'!$A$2:$A$134,'Offensive Data'!$D$2:$X$134)} -> 5.2 | D33: 11.5 | E33: 44.9 | F33: 89.8 | G33: 0.4 | H33: 56.1 | I33: 224 | J33: 4 | K33: 2 | L33: 67.6 | M33: 313.8 | N33: 4.6 | O33: 3.3 | P33: 13.3 | Q33: 1.4 | R33: 18 | S33: 3.2 | T33: 28.8 | U33: 0.4 | V33: 0.8 | W33: 1.3 | X33: {=XLOOKUP(MID(A33, SEARCH("+++", A33) + 3, LEN(A33)),'Defensive Data'!$A$2:$A$134,'Defensive Data'!$D$2:$X$134)} -> #N/A
A34: =CONCATENATE(Scores!A34,"+++",Scores!C34) -> Alabama+++Western Kentucky | B34: =Scores!B34 -> 63 | C34: {=XLOOKUP(LEFT(A34,SEARCH("+",A34)-1),'Offensive Data'!$A$2:$A$134,'Offensive Data'!$D$2:$X$134)} -> 17.4 | D34: 27.2 | E34: 63.8 | F34: 236.4 | G34: 1.3 | H34: 37.5 | I34: 173.8 | J34: 4.6 | K34: 3.2 | L34: 64.8 | M34: 410.2 | N34: 6.3 | O34: 9.8 | P34: 9.7 | Q34: 1.4 | R34: 20.8 | S34: 7.3 | T34: 69.1 | U34: 0.8 | V34: 0.8 | W34: 1.6 | X34: {=XLOOKUP(MID(A34, SEARCH("+++", A34) + 3, LEN(A34)),'Defensive Data'!$A$2:$A$134,'Defensive Data'!$D$2:$X$134)} -> 13.9 | Y34: 22.9 | Z34: 60.7 | AA34: 176.1 | AB34: 1.3 | AC34: 44.2 | AD34: 221.2 | AE34: 5 | AF34: 1.9 | AG34: 67.1 | AH34: 397.3 | AI34: 5.9 | AJ34: 7.4 | AK34: 11.6 | AL34: 1.1 | AM34: 20.1 | AN34: 5.1 | AO34: 44.9 | AP34: 0.7 | AQ34: 0.7 | AR34: 1.4
A35: =CONCATENATE(Scores!A35,"+++",Scores!C35) -> Appalachian State+++East Tennessee State | B35: =Scores!B35 -> 38 | C35: {=XLOOKUP(LEFT(A35,SEARCH("+",A35)-1),'Offensive Data'!$A$2:$A$134,'Offensive Data'!$D$2:$X$134)} -> 19.8 | D35: 35.6 | E35: 55.6 | F35: 273 | G35: 2.1 | H35: 35.2 | I35: 153.8 | J35: 4.4 | K35: 1.2 | L35: 70.8 | M35: 426.8 | N35: 6 | O35: 12.2 | P35: 9.5 | Q35: 2.2 | R35: 23.8 | S35: 6 | T35: 56.9 | U35: 0.5 | V35: 1.5 | W35: 2 | X35: {=XLOOKUP(MID(A35, SEARCH("+++", A35) + 3, LEN(A35)),'Defensive Data'!$A$2:$A$134,'Defensive Data'!$D$2:$X$134)} -> #N/A
A36: =CONCATENATE(Scores!A36,"+++",Scores!C36) -> Arizona+++New Mexico | B36: =Scores!B36 -> 61 | C36: {=XLOOKUP(LEFT(A36,SEARCH("+",A36)-1),'Offensive Data'!$A$2:$A$134,'Offensive Data'!$D$2:$X$134)} -> 21.8 | D36: 36.4 | E36: 60 | F36: 247.9 | G36: 1.5 | H36: 27.9 | I36: 106.6 | J36: 3.8 | K36: 0.9 | L36: 64.3 | M36: 354.5 | N36: 5.5 | O36: 10.8 | P36: 6.2 | Q36: 1.5 | R36: 18.5 | S36: 6.5 | T36: 57.6 | U36: 0.6 | V36: 1.1 | W36: 1.7 | X36: {=XLOOKUP(MID(A36, SEARCH("+++", A36) + 3, LEN(A36)),'Defensive Data'!$A$2:$A$134,'Defensive Data'!$D$2:$X$134)} -> 21.3 | Y36: 33 | Z36: 64.6 | AA36: 279.2 | AB36: 2.5 | AC36: 39.3 | AD36: 212.9 | AE36: 5.4 | AF36: 2.3 | AG36: 72.3 | AH36: 492.1 | AI36: 6.8 | AJ36: 11.7 | AK36: 10.6 | AL36: 2.4 | AM36: 24.7 | AN36: 7 | AO36: 65.4 | AP36: 0.6 | AQ36: 0.3 | AR36: 0.8
A37: =CONCATENATE(Scores!A37,"+++",Scores!C37) -> Arizona State+++Wyoming | B37: =Scores!B37 -> 48 | C37: {=XLOOKUP(LEFT(A37,SEARCH("+",A37)-1),'Offensive Data'!$A$2:$A$134,'Offensive Data'!$D$2:$X$134)} -> 16.7 | D37: 27.3 | E37: 61.3 | F37: 229.5 | G37: 1.9 | H37: 42.2 | I37: 199.9 | J37: 4.7 | K37: 2.1 | L37: 69.5 | M37: 429.4 | N37: 6.2 | O37: 9.6 | P37: 11.1 | Q37: 1.8 | R37: 22.5 | S37: 6.4 | T37: 53.6 | U37: 0.2 | V37: 0.4 | W37: 0.6 | X37: {=XLOOKUP(MID(A37, SEARCH("+++", A37) + 3, LEN(A37)),'Defensive Data'!$A$2:$A$134,'Defensive Data'!$D$2:$X$134)} -> 17.6 | Y37: 28.5 | Z37: 61.7 | AA37: 218.9 | AB37: 1.3 | AC37: 35 | AD37: 191.7 | AE37: 5.5 | AF37: 1.8 | AG37: 63.5 | AH37: 410.6 | AI37: 6.5 | AJ37: 9.8 | AK37: 8.7 | AL37: 1.5 | AM37: 19.9 | AN37: 7.1 | AO37: 58.8 | AP37: 0.4 | AQ37: 0.5 | AR37: 0.9
A38: =CONCATENATE(Scores!A38,"+++",Scores!C38) -> Arkansas State+++Central Arkansas | B38: =Scores!B38 -> 34 | C38: {=XLOOKUP(LEFT(A38,SEARCH("+",A38)-1),'Offensive Data'!$A$2:$A$134,'Offensive Data'!$D$2:$X$134)} -> 21.1 | D38: 34 | E38: 62 | F38: 227.5 | G38: 1.5 | H38: 37.5 | I38: 156.9 | J38: 4.2 | K38: 1.4 | L38: 71.5 | M38: 384.4 | N38: 5.4 | O38: 11.1 | P38: 8.7 | Q38: 2.1 | R38: 21.8 | S38: 5.6 | T38: 51.7 | U38: 0.6 | V38: 0.8 | W38: 1.4 | X38: {=XLOOKUP(MID(A38, SEARCH("+++", A38) + 3, LEN(A38)),'Defensive Data'!$A$2:$A$134,'Defensive Data'!$D$2:$X$134)} -> #N/A
A39: =CONCATENATE(Scores!A39,"+++",Scores!C39) -> Auburn+++Alabama A&M | B39: =Scores!B39 -> 73 | C39: {=XLOOKUP(LEFT(A39,SEARCH("+",A39)-1),'Offensive Data'!$A$2:$A$134,'Offensive Data'!$D$2:$X$134)} -> 19.2 | D39: 30.8 | E39: 62.3 | F39: 263.9 | G39: 2.3 | H39: 33.7 | I39: 165.5 | J39: 4.9 | K39: 1.1 | L39: 64.4 | M39: 429.4 | N39: 6.7 | O39: 10.6 | P39: 9 | Q39: 1.4 | R39: 21 | S39: 5.8 | T39: 49.3 | U39: 0.8 | V39: 1.1 | W39: 1.8 | X39: {=XLOOKUP(MID(A39, SEARCH("+++", A39) + 3, LEN(A39)),'Defensive Data'!$A$2:$A$134,'Defensive Data'!$D$2:$X$134)} -> #N/A
A40: =CONCATENATE(Scores!A40,"+++",Scores!C40) -> Baylor+++Tarleton State | B40: =Scores!B40 -> 45 | C40: {=XLOOKUP(LEFT(A40,SEARCH("+",A40)-1),'Offensive Data'!$A$2:$A$134,'Offensive Data'!$D$2:$X$134)} -> 19.5 | D40: 31.8 | E40: 61.3 | F40: 261.3 | G40: 2.4 | H40: 37.8 | I40: 178.8 | J40: 4.7 | K40: 1.9 | L40: 69.5 | M40: 440.1 | N40: 6.3 | O40: 12.1 | P40: 9.1 | Q40: 1.8 | R40: 23 | S40: 6.2 | T40: 60.4 | U40: 0.4 | V40: 0.8 | W40: 1.2 | X40: {=XLOOKUP(MID(A40, SEARCH("+++", A40) + 3, LEN(A40)),'Defensive Data'!$A$2:$A$134,'Defensive Data'!$D$2:$X$134)} -> #N/A
...

Sheet Scores
A1: Winner | B1: Pts | C1: Loser | D1: Pts
A2: Georgia Tech | B2: 24 | C2: Florida State | D2: 21
A3: Montana State | B3: 35 | C3: New Mexico | D3: 31
A4: Southern Methodist | B4: 29 | C4: Nevada | D4: 24
A5: Hawaii | B5: 35 | C5: Delaware State | D5: 14
A6: Alabama-Birmingham | B6: 41 | C6: Alcorn State | D6: 3
A7: Arkansas | B7: 70 | C7: Arkansas-Pine Bluff | D7: 0
A8: Bowling Green | B8: 41 | C8: Fordham | D8: 17
A9: Buffalo | B9: 30 | C9: Lafayette | D9: 13
A10: Central Florida | B10: 57 | C10: New Hampshire | D10: 3
A11: Central Michigan | B11: 66 | C11: Central Connecticut State | D11: 10
A12: Coastal Carolina | B12: 55 | C12: Jacksonville State | D12: 27
A13: Colorado | B13: 31 | C13: North Dakota State | D13: 26
... A501: New Mexico | B501: 50 | C501: Utah State | D501: 45

Sheet Offensive Data
A1: School | B1: G | C1: Pts | D1: Cmp | E1: Att | F1: Pct | G1: Yds | H1: TD | I1: Att | J1: Yds | K1: Avg | L1: TD | M1: Plays | N1: Yds | O1: Avg | P1: Pass | Q1: Rush | R1: Pen | S1: Tot | T1: No. | U1: Yds | V1: Fum | W1: Int | X1: Tot
A2: Miami (FL) | B2: 13 | C2: 43.9 | D2: 25.2 | E2: 37.6 | F2: 67.1 | G2: 348.2 | H2: 3.2 | I2: 33.3 | J2: 188.9 | K2: 5.7 | L2: 2.3 | M2: 70.9 | N2: 537.2 | O2: 7.6 | P2: 15 | Q2: 10.3 | R2: 1.7 | S2: 27 | T2: 6.6 | U2: 67.5 | V2: 0.6 | W2: 0.6 | X2: 1.2
A3: Indiana | B3: 13 | C3: 41.3 | D3: 18.9 | E3: 27.8 | F3: 68.1 | G3: 261.3 | H3: 2.5 | I3: 37.8 | J3: 165.1 | K3: 4.4 | L3: 2.8 | M3: 65.5 | N3: 426.4 | O3: 6.5 | P3: 11.9 | Q3: 10 | R3: 1.6 | S3: 23.5 | T3: 4.8 | U3: 43.9 | V3: 0.2 | W3: 0.5 | X3: 0.7
A4: Ole Miss | B4: 13 | C4: 38.6 | D4: 22.7 | E4: 33.4 | F4: 68 | G4: 350.8 | H4: 2.4 | I4: 38.5 | J4: 175.7 | K4: 4.6 | L4: 2.2 | M4: 71.8 | N4: 526.5 | O4: 7.3 | P4: 13.5 | Q4: 9.9 | R4: 1.3 | S4: 24.8 | T4: 7.2 | U4: 72 | V4: 0.5 | W4: 0.5 | X4: 1
A5: Texas Tech | B5: 13 | C5: 37.6 | D5: 25.8 | E5: 41.2 | F5: 62.7 | G5: 296.7 | H5: 2.4 | I5: 36.5 | J5: 166 | K5: 4.6 | L5: 2 | M5: 77.7 | N5: 462.7 | O5: 6 | P5: 13.4 | Q5: 9.5 | R5: 1.6 | S5: 24.5 | T5: 7.3 | U5: 60.9 | V5: 0.8 | W5: 0.8 | X5: 1.6
A6: Boise State | B6: 14 | C6: 37.3 | D6: 18.6 | E6: 29.6 | F6: 62.9 | G6: 225.6 | H6: 1.6 | I6: 39.6 | J6: 240.4 | K6: 6.1 | L6: 3.1 | M6: 69.3 | N6: 466 | O6: 6.7 | P6: 11 | Q6: 10.9 | R6: 1.6 | S6: 23.4 | T6: 5.4 | U6: 46.2 | V6: 0.4 | W6: 0.5 | X6: 0.9
A7: Washington State | B7: 13 | C7: 36.6 | D7: 20.2 | E7: 30.7 | F7: 65.9 | G7: 276.1 | H7: 2.5 | I7: 36.2 | J7: 166.8 | K7: 4.6 | L7: 2.2 | M7: 66.8 | N7: 442.8 | O7: 6.6 | P7: 11.8 | Q7: 9.1 | R7: 2 | S7: 22.9 | T7: 6.2 | U7: 57.8 | V7: 0.4 | W7: 0.7 | X7: 1.1
A8: Louisville | B8: 13 | C8: 36.5 | D8: 20.8 | E8: 32.8 | F8: 63.5 | G8: 264.1 | H8: 2 | I8: 32.8 | J8: 185.2 | K8: 5.7 | L8: 2.2 | M8: 65.6 | N8: 449.2 | O8: 6.8 | P8: 11.2 | Q8: 8.5 | R8: 1.5 | S8: 21.2 | T8: 6.2 | U8: 49.4 | V8: 0.4 | W8: 0.5 | X8: 0.8
A9: SMU | B9: 14 | C9: 36.5 | D9: 19.9 | E9: 31.1 | F9: 63.8 | G9: 261.9 | H9: 2 | I9: 38.7 | J9: 167.6 | K9: 4.3 | L9: 2.1 | M9: 69.9 | N9: 429.5 | O9: 6.1 | P9: 11.4 | Q9: 9.5 | R9: 1.9 | S9: 22.8 | T9: 8.1 | U9: 77.7 | V9: 0.9 | W9: 0.9 | X9: 1.7
A10: Texas State | B10: 13 | C10: 36.5 | D10: 23 | E10: 32.9 | F10: 69.9 | G10: 268.7 | H10: 2.4 | I10: 40.7 | J10: 208.2 | K10: 5.1 | L10: 2.1 | M10: 73.6 | N10: 476.9 | O10: 6.5 | P10: 12.4 | Q10: 12.1 | R10: 1.6 | S10: 26.1 | T10: 6.8 | U10: 64.2 | V10: 0.7 | W10: 1.1 | X10: 1.8
A11: Notre Dame | B11: 16 | C11: 36.1 | D11: 18.5 | E11: 27.8 | F11: 66.5 | G11: 198.1 | H11: 1.5 | I11: 35.5 | J11: 200.9 | K11: 5.7 | L11: 2.8 | M11: 63.3 | N11: 399.1 | O11: 6.3 | P11: 9.4 | Q11: 9.2 | R11: 1.8 | S11: 20.4 | T11: 5.8 | U11: 50.9 | V11: 0.4 | W11: 0.5 | X11: 0.9
A12: Jacksonville State | B12: 14 | C12: 36 | D12: 13.5 | E12: 22.4 | F12: 60.2 | G12: 190.4 | H12: 1 | I12: 46.1 | J12: 251.2 | K12: 5.4 | L12: 3.6 | M12: 68.6 | N12: 441.6 | O12: 6.4 | P12: 7.6 | Q12: 12.8 | R12: 2.4 | S12: 22.7 | T12: 5.9 | U12: 57.7 | V12: 0.6 | W12: 0.5 | X12: 1.1
A13: Memphis | B13: 13 | C13: 35.7 | D13: 23.8 | E13: 36.8 | F13: 64.7 | G13: 270.5 | H13: 1.9 | I13: 34.5 | J13: 174.1 | K13: 5.1 | L13: 2.5 | M13: 71.3 | N13: 444.5 | O13: 6.2 | P13: 11.5 | Q13: 9.4 | R13: 2.2 | S13: 23.1 | T13: 5.3 | U13: 48 | V13: 0.2 | W13: 0.5 | X13: 0.6
... A135: Kent State | B135: 12 | C135: 13.9 | D135: 11.6 | E135: 24.5 | F135: 47.3 | G135: 156.3 | H135: 1.5 | I135: 32.6 | J135: 76.9 | K135: 2.4 | L135: 0.3 | M135: 57.1 | N135: 233.3 | O135: 4.1 | P135: 5.8 | Q135: 5.1 | R135: 2.1 | S135: 13 | T135: 4.9 | U135: 35.8 | V135: 0.6 | W135: 1.1 | X135: 1.7

Sheet Defensive Data
A1: School | B1: G | C1: Pts | D1: Cmp | E1: Att | F1: Pct | G1: Yds | H1: TD | I1: Att | J1: Yds | K1: Avg | L1: TD | M1: Plays | N1: Yds | O1: Avg | P1: Pass | Q1: Rush | R1: Pen | S1: Tot | T1: No. | U1: Yds | V1: Fum | W1: Int | X1: TO
A2: Ohio State | B2: 16 | C2: 12.9 | D2: 16.7 | E2: 27.6 | F2: 60.4 | G2: 167 | H2: 0.6 | I2: 33.1 | J2: 87.6 | K2: 2.6 | L2: 0.8 | M2: 60.8 | N2: 254.6 | O2: 4.2 | P2: 7.3 | Q2: 6.1 | R2: 1.7 | S2: 15.1 | T2: 3.7 | U2: 29.2 | V2: 0.6 | W2: 0.6 | X2: 1.2
A3: Ole Miss | B3: 13 | C3: 14.4 | D3: 20.5 | E3: 34.4 | F3: 59.7 | G3: 230.8 | H3: 1 | I3: 35.1 | J3: 80.5 | K3: 2.3 | L3: 0.5 | M3: 69.5 | N3: 311.2 | O3: 4.5 | P3: 10.2 | Q3: 5.8 | R3: 2.5 | S3: 18.6 | T3: 6.2 | U3: 53.8 | V3: 0.8 | W3: 0.9 | X3: 1.8
A4: Texas | B4: 16 | C4: 15.3 | D4: 18.3 | E4: 30.6 | F4: 59.7 | G4: 173.8 | H4: 0.6 | I4: 33.9 | J4: 109.6 | K4: 3.2 | L4: 0.9 | M4: 64.4 | N4: 283.4 | O4: 4.4 | P4: 8.4 | Q4: 6.5 | R4: 1.5 | S4: 16.4 | T4: 5.6 | U4: 47.8 | V4: 0.6 | W4: 1.4 | X4: 1.9
A5: Army | B5: 14 | C5: 15.5 | D5: 18.1 | E5: 28.7 | F5: 62.9 | G5: 185.9 | H5: 1.1 | I5: 27.2 | J5: 112 | K5: 4.1 | L5: 0.9 | M5: 55.9 | N5: 297.9 | O5: 5.3 | P5: 8.4 | Q5: 7 | R5: 0.9 | S5: 16.4 | T5: 4.6 | U5: 40.5 | V5: 0.1 | W5: 1.3 | X5: 1.4
A6: Notre Dame | B6: 16 | C6: 15.5 | D6: 14.7 | E6: 28.2 | F6: 52.1 | G6: 169.4 | H6: 0.9 | I6: 36.5 | J6: 138.1 | K6: 3.8 | L6: 1 | M6: 64.7 | N6: 307.4 | O6: 4.8 | P6: 7.4 | Q6: 7.9 | R6: 1.8 | S6: 17 | T6: 5.4 | U6: 48.3 | V6: 0.9 | W6: 1.2 | X6: 2.1
A7: Indiana | B7: 13 | C7: 15.6 | D7: 19.1 | E7: 30.5 | F7: 62.5 | G7: 176.1 | H7: 0.8 | I7: 29.2 | J7: 81.2 | K7: 2.8 | L7: 0.9 | M7: 59.8 | N7: 257.2 | O7: 4.3 | P7: 8 | Q7: 5.2 | R7: 1.5 | S7: 14.8 | T7: 5.8 | U7: 44.9 | V7: 0.7 | W7: 1.2 | X7: 1.8
A8: Tennessee | B8: 13 | C8: 16.1 | D8: 17.2 | E8: 29.3 | F8: 58.8 | G8: 189.3 | H8: 0.8 | I8: 35 | J8: 103.9 | K8: 3 | L8: 1 | M8: 64.3 | N8: 293.2 | O8: 4.6 | P8: 8.8 | Q8: 6.6 | R8: 1.9 | S8: 17.3 | T8: 6.8 | U8: 53.2 | V8: 0.7 | W8: 0.9 | X8: 1.6
A9: Penn State | B9: 16 | C9: 16.5 | D9: 17.8 | E9: 29.7 | F9: 60 | G9: 192.9 | H9: 1.1 | I9: 33.4 | J9: 101.9 | K9: 3.1 | L9: 0.6 | M9: 63.1 | N9: 294.8 | O9: 4.7 | P9: 8.8 | Q9: 7.2 | R9: 1.6 | S9: 17.6 | T9: 4.4 | U9: 33.9 | V9: 0.4 | W9: 1.3 | X9: 1.6
A10: Minnesota | B10: 13 | C10: 16.9 | D10: 16.9 | E10: 28.7 | F10: 59 | G10: 176.1 | H10: 0.8 | I10: 31.3 | J10: 109.6 | K10: 3.5 | L10: 1.1 | M10: 60 | N10: 285.7 | O10: 4.8 | P10: 8.5 | Q10: 5.9 | R10: 1.5 | S10: 16 | T10: 5 | U10: 49.1 | V10: 0.3 | W10: 1.3 | X10: 1.6
A11: Alabama | B11: 13 | C11: 17.4 | D11: 18.2 | E11: 30.4 | F11: 59.7 | G11: 182.2 | H11: 1 | I11: 37.5 | J11: 137.8 | K11: 3.7 | L11: 0.8 | M11: 67.8 | N11: 320.1 | O11: 4.7 | P11: 8.6 | Q11: 7.7 | R11: 2.5 | S11: 18.8 | T11: 5.8 | U11: 47.8 | V11: 0.8 | W11: 1.3 | X11: 2.2
A12: Iowa | B12: 13 | C12: 17.8 | D12: 20 | E12: 32.3 | F12: 61.9 | G12: 203.1 | H12: 1.5 | I12: 31.2 | J12: 115.3 | K12: 3.7 | L12: 0.3 | M12: 63.5 | N12: 318.4 | O12: 5 | P12: 9.5 | Q12: 7.2 | R12: 1.1 | S12: 17.7 | T12: 5.7 | U12: 44.7 | V12: 0.6 | W12: 1.2 | X12: 1.8
A13: Ohio | B13: 14 | C13: 18.1 | D13: 18.9 | E13: 31 | F13: 61.1 | G13: 212.6 | H13: 1.1 | I13: 30.7 | J13: 90.6 | K13: 2.9 | L13: 1 | M13: 61.7 | N13: 303.1 | O13: 4.9 | P13: 9.8 | Q13: 5.8 | R13: 1 | S13: 16.6 | T13: 5.7 | U13: 52.4 | V13: 0.6 | W13: 0.8 | X13: 1.4
... A135: Kent State | B135: 12 | C135: 44.1 | D135: 18.8 | E135: 28.8 | F135: 65.3 | G135: 251.1 | H135: 2.3 | I135: 44.9 | J135: 264.9 | K135: 5.9 | L135: 3 | M135: 73.8 | N135: 516 | O135: 7 | P135: 11.3 | Q135: 13.3 | R135: 1.8 | S135: 26.4 | T135: 5.9 | U135: 56.3 | V135: 0.6 | W135: 0.3 | X135: 0.9
